<?xml version="1.0" ?>
<robot name="my_robot">

    <link name="base_link">

        <collision>
	        <origin xyz="0.0 0.0 0.0" rpy="0.0 0.0 0.0" />
            <geometry>
                <cylinder length="0.16" radius="0.20" />
            </geometry>        
        </collision>

        <visual>
	        <origin xyz="0.0 0.0 0.0" rpy="0.0 0.0 0.0" />
            <geometry>
                <cylinder length="0.16" radius="0.20" />
            </geometry>
	        <material name="orange">
                <color rgba="1 0.4 0 1"/>
            </material>
        </visual>

	    <inertial>
            <origin xyz="0 0 0" rpy="0 0 0"/>
            <mass value="6" />
            <inertia ixx="0.06228" ixy="0" ixz="0" iyy="0.06228" iyz="0" izz="0.12" />
        </inertial>
    </link>

    <!-- <link name="dummy">
    </link>
    <joint name="dummy_joint" type="fixed">
        <parent link="dummy"/>
        <child link="base_link"/>
    </joint> -->

    <!-- <link name="base_footprint"/> -->
    <link name="base_footprint">
        <visual>
            <geometry>
                <box size="0.001 0.001 0.001" />
            </geometry>
        </visual>
    </link>

    <joint name="base_footprint2base_link" type="fixed">
        <parent link="base_footprint" />
        <child link="base_link" />
        <origin xyz="0 0 0.11" rpy="0 0 0"/>
    </joint>

    <gazebo reference="base_link">
    	<material>Gazebo/Orange</material>
    </gazebo>

    <link name="left_wheel_link">
        <collision>
            <origin xyz="0 0 0" rpy="1.5707 0 0" />
            <geometry>
                <cylinder radius="0.06" length = "0.025"/>
            </geometry>
        </collision>

        <visual>
            <origin xyz="0 0 0" rpy="1.5707 0 0" />
            <geometry>
                <cylinder radius="0.06" length = "0.025"/>
            </geometry>
        </visual>

	    <inertial>
            <origin xyz="0 0 0"/>
            <mass value="1" />
            <inertia ixx="0.000952083" ixy="0" ixz="0" iyy="0.000952083" iyz="0" izz="0.0018" />
        </inertial>		
    </link>

    <joint name="left_wheel_joint" type="continuous">
        <parent link="base_link"/>
        <child link="left_wheel_link"/>
        <axis xyz="0 1 0"/>
        <origin xyz="0 0.19 -0.05" rpy="0 0 0"/>
    </joint>

    <joint name="right_wheel_joint" type="continuous">
        <origin xyz="0 -0.19 -0.05" rpy="0 0 0"/>
        <parent link="base_link"/>
        <child link="right_wheel_link"/>
        <axis xyz="0 1 0"/>
    </joint>

    <link name="right_wheel_link">
        <collision>
            <origin xyz="0 0 0" rpy="1.5707 0 0" />
            <geometry>
                <cylinder radius="0.06" length = "0.025"/>
            </geometry>
        </collision>

        <visual>
            <origin xyz="0 0 0" rpy="1.5707 0 0" />
            <geometry>
                <cylinder radius="0.06" length = "0.025"/>
            </geometry>
        </visual>

	    <inertial>
            <origin xyz="0 0 0"/>
            <mass value="1" />
            <inertia ixx="0.000952083" ixy="0" ixz="0" iyy="0.000952083" iyz="0" izz="0.0018" />
        </inertial>
    </link>



    <joint name="front_caster_joint" type="continuous">
        <origin xyz="0.18 0 -0.095" rpy="0 0 0"/>
        <parent link="base_link"/>
        <child link="front_caster_link"/>
        <axis xyz="0 1 0"/>
    </joint>

    <link name="front_caster_link">
	    <collision>
	        <origin xyz="0 0 0" rpy="0 0 0" />
            <geometry>
                <sphere radius="0.015"/>
            </geometry>
	    </collision>

        <visual>
            <origin xyz="0 0 0" rpy="0 0 0"/>
            <geometry>
                <sphere radius="0.015" />
            </geometry>
        </visual>

        <inertial>
            <origin xyz="0 0 0"/>
            <mass value="1" />
            <inertia ixx="0.000009" ixy="0" ixz="0" iyy="0.000009" iyz="0" izz="0.000009" />
        </inertial>
    </link>

    <joint name="back_caster_joint" type="continuous">
        <origin xyz="-0.18 0 -0.095" rpy="0 0 0"/>
        <parent link="base_link"/>
        <child link="back_caster_link"/>
        <axis xyz="0 1 0"/>
    </joint>

    <link name="back_caster_link">
        <collision>
            <origin xyz="0 0 0" rpy="0 0 0" />
            <geometry>
                <sphere radius="0.015"/>
            </geometry>
        </collision>

        <visual>
            <origin xyz="0 0 0" rpy="0 0 0"/>
            <geometry>
                <sphere radius="0.015" />
            </geometry>
        </visual>

	    <inertial>
            <origin xyz="0 0 0"/>
            <mass value="1" />
            <inertia ixx="0.000009" ixy="0" ixz="0" iyy="0.000009" iyz="0" izz="0.000009" />
        </inertial>
    </link>

     <link name="camera_support_link">
        <collision>
            <origin xyz=" 0 0 0 " rpy="0 0 0" />
                <geometry>          
                    <box size="0.02 0.05 0.01" />
                </geometry>
        </collision>

        <visual>
            <origin xyz=" 0 0 0 " rpy="0 0 0" />
            <geometry>          
                <box size="0.02 0.05 0.01" />
            </geometry>
            <material name="white"/>
        </visual>

	    <inertial>
            <origin xyz="0 0 0"/>
            <mass value="1" />
            <inertia ixx="0.000283333" ixy="0" ixz="0" iyy="0.000108333" iyz="0" izz="0.000241667" />
        </inertial>
    </link>


    <joint name="camera_support_joint" type="fixed">
        <origin xyz="0.17 0 0.085" rpy="0 0 0"/>
        <parent link="base_link"/>
        <child link="camera_support_link"/>
    </joint>


    <link name="camera_link">
        <collision>
            <origin xyz=" 0 0 0 " rpy="0 0 0" />
                <geometry>          
                    <box size="0.02 0.05 0.03" />
                </geometry>
        </collision>

        <visual>
            <origin xyz=" 0 0 0 " rpy="0 0 0" />
            <geometry>          
                <box size="0.02 0.05 0.03" />
            </geometry>
            <material name="black">
                <color rgba="0 0 0 0.95"/>
            </material>
        </visual>

	    <inertial>
            <origin xyz="0 0 0"/>
            <mass value="1" />
            <inertia ixx="0.000283333" ixy="0" ixz="0" iyy="0.000108333" iyz="0" izz="0.000241667" />
        </inertial>
    </link>

    <gazebo reference="camera_link">
   	    <material>Gazebo/Black</material>
	    <sensor type="camera" name="camera1">
            <update_rate>30.0</update_rate>
            <camera name="head">
                <horizontal_fov>1.3962634</horizontal_fov>
                <image>
                    <width>800</width>
                    <height>800</height>
                    <format>R8G8B8</format>
                </image>
                <clip>
                    <near>0.02</near>
                    <far>300</far>
                </clip>
                <noise>
                    <type>gaussian</type>
                    <!-- Noise is sampled independently per pixel on each frame.
                        That pixel's noise value is added to each of its color
                        channels, which at that point lie in the range [0,1]. -->
                    <mean>0.0</mean>
                    <stddev>0.007</stddev>
                </noise>
            </camera>
            <plugin name="camera_controller" filename="libgazebo_ros_camera.so">
                <alwaysOn>true</alwaysOn>
                <updateRate>0.0</updateRate>
                <cameraName>rrbot/camera1</cameraName>
                <imageTopicName>image_raw</imageTopicName>
                <cameraInfoTopicName>camera_info</cameraInfoTopicName>
                <frameName>camera_link</frameName>
                <hackBaseline>0.07</hackBaseline>
                <distortionK1>0.0</distortionK1>
                <distortionK2>0.0</distortionK2>
                <distortionK3>0.0</distortionK3>
                <distortionT1>0.0</distortionT1>
                <distortionT2>0.0</distortionT2>
            </plugin>
	    </sensor>
    </gazebo>

    <joint name="camera_joint" type="fixed">
        <origin xyz="0 0 0.02" rpy="0 0 0"/>
        <parent link="camera_support_link"/>
        <child link="camera_link"/>
    </joint>

    <link name="laser_support_link">
        <collision>
            <origin xyz=" 0 0 0 " rpy="0 0 0" />
            <geometry>
                    <cylinder length="0.03" radius="0.05"/>
            </geometry>
        </collision>

        <visual>
            <origin xyz=" 0 0 0 " rpy="0 0 0" />
            <geometry>
                <cylinder length="0.03" radius="0.05"/>
            </geometry>
            <material name="white"/>
        </visual>

	    <inertial>
            <origin xyz="0 0 0"/>
            <mass value="1" />
            <inertia ixx="0.0007" ixy="0" ixz="0" iyy="0.0007" iyz="0" izz="0.00125" />
        </inertial>
    </link>

    <joint name="laser_support_joint" type="fixed">
        <origin xyz="0 0 0.095" rpy="0 0 0"/>
        <parent link="base_link"/>
        <child link="laser_support_link"/>
    </joint>

    <link name="laser_link">
        <collision>
            <origin xyz=" 0 0 0 " rpy="0 0 0" />
            <geometry>
                    <cylinder length="0.05" radius="0.05"/>
            </geometry>
        </collision>

        <visual>
            <origin xyz=" 0 0 0 " rpy="0 0 0" />
            <geometry>
                <cylinder length="0.05" radius="0.05"/>
            </geometry>
            <material name="black"/>
        </visual>

	    <inertial>
            <origin xyz="0 0 0"/>
            <mass value="1" />
            <inertia ixx="0.000083333" ixy="0" ixz="0" iyy="0.000083333" iyz="0" izz="0.00125" />
        </inertial>
    </link>

    <gazebo reference="laser_link">
   	    <material>Gazebo/Black</material>
	    <sensor type="gpu_ray" name="head_hokuyo_sensor">
      	   <pose>0 0 0 0 0 0</pose>
      	   <visualize>false</visualize>
      	   <update_rate>40</update_rate>
      	   <ray>
                <scan>
                    <horizontal>
                            <samples>1440</samples>
                            <resolution>1</resolution>
                            <min_angle>-3.1415926</min_angle>
                            <max_angle>3.1415926</max_angle>
                    </horizontal>
                </scan>
                <range>
                    <min>0.10</min>
                    <max>80.0</max>
                    <resolution>0.01</resolution>
                </range>
                <noise>
                    <type>gaussian</type>
                    <!-- Noise parameters based on published spec for Hokuyo laser
                    achieving "+-30mm" accuracy at range < 10m.  A mean of 0.0m and
                    stddev of 0.01m will put 99.7% of samples within 0.03m of the true
                    reading. -->
                    <mean>0.0</mean>
                    <stddev>0.01</stddev>
                </noise>
      	   </ray>
       	   <plugin name="gazebo_ros_head_hokuyo_controller" filename="libgazebo_ros_gpu_laser.so">
                <topicName>/scan</topicName>
                <frameName>laser_link</frameName>
      	   </plugin>
    	</sensor>
    </gazebo>

    <joint name="laser_joint" type="fixed">
        <origin xyz="0 0 0.04" rpy="0 0 0"/>
        <parent link="laser_support_link"/>
        <child link="laser_link"/>
    </joint>

   <link name="imu_link">
        <collision>
            <origin xyz=" 0 0 0 " rpy="0 0 0" />
            <geometry>          
                <box size="0.02 0.02 0.01" />
            </geometry>
        </collision>

        <visual>
            <origin xyz=" 0 0 0 " rpy="0 0 0" />
            <geometry>          
                <box size="0.02 0.02 0.01" />
            </geometry>
        </visual>

	    <inertial>
            <origin xyz="0 0 0"/>
            <mass value="0.5" />
            <inertia ixx="0.000020833" ixy="0" ixz="0" iyy="0.000020833" iyz="0" izz="0.000033333" />
        </inertial>
    </link>

    <gazebo reference="imu_link">
        <gravity>true</gravity>
        <sensor name="imu_sensor" type="imu">
            <always_on>true</always_on>
            <update_rate>100</update_rate>
            <visualize>true</visualize>
            <topic>__default_topic__</topic>
            <plugin filename="libgazebo_ros_imu_sensor.so" name="imu_plugin">
                <topicName>imu</topicName>
                <bodyName>imu_link</bodyName>
                <updateRateHZ>10.0</updateRateHZ>
                <gaussianNoise>0.0</gaussianNoise>
                <xyzOffset>0 0 0</xyzOffset>
                <rpyOffset>0 0 0</rpyOffset>
                <frameName>imu_link</frameName>
                <initialOrientationAsReference>false</initialOrientationAsReference>
            </plugin>
            <pose>0 0 0 0 0 0</pose>
        </sensor>
    </gazebo>

    <joint name="imu_joint" type="fixed">
        <origin xyz="0.1 0 0.085" rpy="0 0 0"/>
        <parent link="base_link"/>
        <child link="imu_link"/>
    </joint>

    <gazebo>
        <plugin name="differential_drive_controller" filename="libgazebo_ros_diff_drive.so">
            <rosDebuglevel>Debug</rosDebuglevel>
            <publishWheelTF>false</publishWheelTF>
            <publishTF>1</publishTF>
            <publishWheelJointState>false</publishWheelJointState>
            <updateRate>100.0</updateRate>
            <leftJoint>left_wheel_joint</leftJoint>
            <rightJoint>right_wheel_joint</rightJoint>
            <wheelSeparation>0.4</wheelSeparation>
            <wheelDiameter>0.12</wheelDiameter>
            <wheelAcceleration>1.8</wheelAcceleration>
            <commandTopic>cmd_vel</commandTopic>
            <odometryTopic>odom</odometryTopic>
            <robotBaseFrame>base_footprint</robotBaseFrame>
            <odometryFrame>odom</odometryFrame>
            <broadcastTF>1</broadcastTF>
        </plugin>
    </gazebo>

  <gazebo>
        <plugin name="gazebo_ros_control" filename="libgazebo_ros_control.so">
            <robotNamespace>/my_robot</robotNamespace>
        </plugin>
  </gazebo>

</robot>
